[2023-06-09 08:18:23,704] {taskinstance.py:1037} INFO - Dependencies all met for <TaskInstance: my_dag.dbt-1 manual__2023-06-09T08:18:23.014732+00:00 [queued]>
[2023-06-09 08:18:23,711] {taskinstance.py:1037} INFO - Dependencies all met for <TaskInstance: my_dag.dbt-1 manual__2023-06-09T08:18:23.014732+00:00 [queued]>
[2023-06-09 08:18:23,711] {taskinstance.py:1243} INFO - 
--------------------------------------------------------------------------------
[2023-06-09 08:18:23,711] {taskinstance.py:1244} INFO - Starting attempt 1 of 1
[2023-06-09 08:18:23,711] {taskinstance.py:1245} INFO - 
--------------------------------------------------------------------------------
[2023-06-09 08:18:23,723] {taskinstance.py:1264} INFO - Executing <Task(BashOperator): dbt-1> on 2023-06-09 08:18:23.014732+00:00
[2023-06-09 08:18:23,727] {standard_task_runner.py:52} INFO - Started process 1926 to run task
[2023-06-09 08:18:23,729] {standard_task_runner.py:76} INFO - Running: ['***', 'tasks', 'run', 'my_dag', 'dbt-1', 'manual__2023-06-09T08:18:23.014732+00:00', '--job-id', '18', '--raw', '--subdir', 'DAGS_FOLDER/dag.py', '--cfg-path', '/tmp/tmpkneo24zd', '--error-file', '/tmp/tmpcf_nwnrd']
[2023-06-09 08:18:23,729] {standard_task_runner.py:77} INFO - Job 18: Subtask dbt-1
[2023-06-09 08:18:23,764] {logging_mixin.py:109} INFO - Running <TaskInstance: my_dag.dbt-1 manual__2023-06-09T08:18:23.014732+00:00 [running]> on host 00a2553a67b9
[2023-06-09 08:18:23,816] {taskinstance.py:1431} INFO - Exporting the following env vars:
AIRFLOW_CTX_DAG_OWNER=***
AIRFLOW_CTX_DAG_ID=my_dag
AIRFLOW_CTX_TASK_ID=dbt-1
AIRFLOW_CTX_EXECUTION_DATE=2023-06-09T08:18:23.014732+00:00
AIRFLOW_CTX_DAG_RUN_ID=manual__2023-06-09T08:18:23.014732+00:00
[2023-06-09 08:18:23,818] {subprocess.py:62} INFO - Tmp dir root location: 
 /tmp
[2023-06-09 08:18:23,819] {subprocess.py:74} INFO - Running command: ['bash', '-c', 'dbt run --models dbt-1 --profiles-dir /opt/***/dbt/part3/profiles.yml --project-dir /opt/***/dbt/part3/']
[2023-06-09 08:18:23,841] {subprocess.py:85} INFO - Output:
[2023-06-09 08:18:27,333] {subprocess.py:89} INFO - [0m08:18:27  Encountered an error:
[2023-06-09 08:18:27,333] {subprocess.py:89} INFO - [Errno 13] Permission denied: '/opt/***/dbt/part3/logs/dbt.log'
[2023-06-09 08:18:27,334] {subprocess.py:89} INFO - [0m08:18:27  Traceback (most recent call last):
[2023-06-09 08:18:27,334] {subprocess.py:89} INFO -   File "/home/***/.local/lib/python3.7/site-packages/dbt/cli/requires.py", line 86, in wrapper
[2023-06-09 08:18:27,334] {subprocess.py:89} INFO -     result, success = func(*args, **kwargs)
[2023-06-09 08:18:27,334] {subprocess.py:89} INFO -   File "/home/***/.local/lib/python3.7/site-packages/dbt/cli/requires.py", line 47, in wrapper
[2023-06-09 08:18:27,334] {subprocess.py:89} INFO -     setup_event_logger(flags=flags, callbacks=callbacks)
[2023-06-09 08:18:27,334] {subprocess.py:89} INFO -   File "/home/***/.local/lib/python3.7/site-packages/dbt/events/functions.py", line 66, in setup_event_logger
[2023-06-09 08:18:27,334] {subprocess.py:89} INFO -     log_file, flags.USE_COLORS_FILE, log_file_format, log_level_file
[2023-06-09 08:18:27,334] {subprocess.py:89} INFO -   File "/home/***/.local/lib/python3.7/site-packages/dbt/events/eventmgr.py", line 211, in add_logger
[2023-06-09 08:18:27,334] {subprocess.py:89} INFO -     else _TextLogger(self, config)
[2023-06-09 08:18:27,334] {subprocess.py:89} INFO -   File "/home/***/.local/lib/python3.7/site-packages/dbt/events/eventmgr.py", line 132, in __init__
[2023-06-09 08:18:27,334] {subprocess.py:89} INFO -     super().__init__(event_manager, config)
[2023-06-09 08:18:27,334] {subprocess.py:89} INFO -   File "/home/***/.local/lib/python3.7/site-packages/dbt/events/eventmgr.py", line 104, in __init__
[2023-06-09 08:18:27,334] {subprocess.py:89} INFO -     backupCount=5,
[2023-06-09 08:18:27,334] {subprocess.py:89} INFO -   File "/usr/local/lib/python3.7/logging/handlers.py", line 148, in __init__
[2023-06-09 08:18:27,334] {subprocess.py:89} INFO -     BaseRotatingHandler.__init__(self, filename, mode, encoding, delay)
[2023-06-09 08:18:27,334] {subprocess.py:89} INFO -   File "/usr/local/lib/python3.7/logging/handlers.py", line 55, in __init__
[2023-06-09 08:18:27,334] {subprocess.py:89} INFO -     logging.FileHandler.__init__(self, filename, mode, encoding, delay)
[2023-06-09 08:18:27,334] {subprocess.py:89} INFO -   File "/usr/local/lib/python3.7/logging/__init__.py", line 1087, in __init__
[2023-06-09 08:18:27,334] {subprocess.py:89} INFO -     StreamHandler.__init__(self, self._open())
[2023-06-09 08:18:27,335] {subprocess.py:89} INFO -   File "/usr/local/lib/python3.7/logging/__init__.py", line 1116, in _open
[2023-06-09 08:18:27,335] {subprocess.py:89} INFO -     return open(self.baseFilename, self.mode, encoding=self.encoding)
[2023-06-09 08:18:27,335] {subprocess.py:89} INFO - PermissionError: [Errno 13] Permission denied: '/opt/***/dbt/part3/logs/dbt.log'
[2023-06-09 08:18:27,335] {subprocess.py:89} INFO - 
[2023-06-09 08:18:27,430] {subprocess.py:93} INFO - Command exited with return code 2
[2023-06-09 08:18:27,439] {taskinstance.py:1718} ERROR - Task failed with exception
Traceback (most recent call last):
  File "/home/airflow/.local/lib/python3.7/site-packages/airflow/models/taskinstance.py", line 1334, in _run_raw_task
    self._execute_task_with_callbacks(context)
  File "/home/airflow/.local/lib/python3.7/site-packages/airflow/models/taskinstance.py", line 1460, in _execute_task_with_callbacks
    result = self._execute_task(context, self.task)
  File "/home/airflow/.local/lib/python3.7/site-packages/airflow/models/taskinstance.py", line 1516, in _execute_task
    result = execute_callable(context=context)
  File "/home/airflow/.local/lib/python3.7/site-packages/airflow/operators/bash.py", line 188, in execute
    f'Bash command failed. The command returned a non-zero exit code {result.exit_code}.'
airflow.exceptions.AirflowException: Bash command failed. The command returned a non-zero exit code 2.
[2023-06-09 08:18:27,444] {taskinstance.py:1282} INFO - Marking task as FAILED. dag_id=my_dag, task_id=dbt-1, execution_date=20230609T081823, start_date=20230609T081823, end_date=20230609T081827
[2023-06-09 08:18:27,455] {standard_task_runner.py:92} ERROR - Failed to execute job 18 for task dbt-1
Traceback (most recent call last):
  File "/home/airflow/.local/lib/python3.7/site-packages/airflow/task/task_runner/standard_task_runner.py", line 85, in _start_by_fork
    args.func(args, dag=self.dag)
  File "/home/airflow/.local/lib/python3.7/site-packages/airflow/cli/cli_parser.py", line 48, in command
    return func(*args, **kwargs)
  File "/home/airflow/.local/lib/python3.7/site-packages/airflow/utils/cli.py", line 92, in wrapper
    return f(*args, **kwargs)
  File "/home/airflow/.local/lib/python3.7/site-packages/airflow/cli/commands/task_command.py", line 298, in task_run
    _run_task_by_selected_method(args, dag, ti)
  File "/home/airflow/.local/lib/python3.7/site-packages/airflow/cli/commands/task_command.py", line 107, in _run_task_by_selected_method
    _run_raw_task(args, ti)
  File "/home/airflow/.local/lib/python3.7/site-packages/airflow/cli/commands/task_command.py", line 184, in _run_raw_task
    error_file=args.error_file,
  File "/home/airflow/.local/lib/python3.7/site-packages/airflow/utils/session.py", line 70, in wrapper
    return func(*args, session=session, **kwargs)
  File "/home/airflow/.local/lib/python3.7/site-packages/airflow/models/taskinstance.py", line 1334, in _run_raw_task
    self._execute_task_with_callbacks(context)
  File "/home/airflow/.local/lib/python3.7/site-packages/airflow/models/taskinstance.py", line 1460, in _execute_task_with_callbacks
    result = self._execute_task(context, self.task)
  File "/home/airflow/.local/lib/python3.7/site-packages/airflow/models/taskinstance.py", line 1516, in _execute_task
    result = execute_callable(context=context)
  File "/home/airflow/.local/lib/python3.7/site-packages/airflow/operators/bash.py", line 188, in execute
    f'Bash command failed. The command returned a non-zero exit code {result.exit_code}.'
airflow.exceptions.AirflowException: Bash command failed. The command returned a non-zero exit code 2.
[2023-06-09 08:18:27,472] {local_task_job.py:154} INFO - Task exited with return code 1
[2023-06-09 08:18:27,513] {local_task_job.py:264} INFO - 0 downstream tasks scheduled from follow-on schedule check
