[2023-06-09 13:43:09,633] {taskinstance.py:1037} INFO - Dependencies all met for <TaskInstance: my_dag.dbt-1 manual__2023-06-09T13:43:08.546128+00:00 [queued]>
[2023-06-09 13:43:09,639] {taskinstance.py:1037} INFO - Dependencies all met for <TaskInstance: my_dag.dbt-1 manual__2023-06-09T13:43:08.546128+00:00 [queued]>
[2023-06-09 13:43:09,639] {taskinstance.py:1243} INFO - 
--------------------------------------------------------------------------------
[2023-06-09 13:43:09,639] {taskinstance.py:1244} INFO - Starting attempt 1 of 1
[2023-06-09 13:43:09,639] {taskinstance.py:1245} INFO - 
--------------------------------------------------------------------------------
[2023-06-09 13:43:09,649] {taskinstance.py:1264} INFO - Executing <Task(BashOperator): dbt-1> on 2023-06-09 13:43:08.546128+00:00
[2023-06-09 13:43:09,653] {standard_task_runner.py:52} INFO - Started process 5703 to run task
[2023-06-09 13:43:09,654] {standard_task_runner.py:76} INFO - Running: ['***', 'tasks', 'run', 'my_dag', 'dbt-1', 'manual__2023-06-09T13:43:08.546128+00:00', '--job-id', '30', '--raw', '--subdir', 'DAGS_FOLDER/dag.py', '--cfg-path', '/tmp/tmpv0g44fv8', '--error-file', '/tmp/tmpm3grw8hu']
[2023-06-09 13:43:09,655] {standard_task_runner.py:77} INFO - Job 30: Subtask dbt-1
[2023-06-09 13:43:09,749] {logging_mixin.py:109} INFO - Running <TaskInstance: my_dag.dbt-1 manual__2023-06-09T13:43:08.546128+00:00 [running]> on host d78e0722255b
[2023-06-09 13:43:09,816] {taskinstance.py:1431} INFO - Exporting the following env vars:
AIRFLOW_CTX_DAG_OWNER=***
AIRFLOW_CTX_DAG_ID=my_dag
AIRFLOW_CTX_TASK_ID=dbt-1
AIRFLOW_CTX_EXECUTION_DATE=2023-06-09T13:43:08.546128+00:00
AIRFLOW_CTX_DAG_RUN_ID=manual__2023-06-09T13:43:08.546128+00:00
[2023-06-09 13:43:09,818] {subprocess.py:62} INFO - Tmp dir root location: 
 /tmp
[2023-06-09 13:43:09,818] {subprocess.py:74} INFO - Running command: ['bash', '-c', 'dbt run --models dbt1 --profiles-dir /opt/***/dbt/part3/ --project-dir /opt/***/dbt/part3/']
[2023-06-09 13:43:09,829] {subprocess.py:85} INFO - Output:
[2023-06-09 13:43:12,027] {subprocess.py:89} INFO - [0m13:43:12  Running with dbt=1.5.1
[2023-06-09 13:43:12,129] {subprocess.py:89} INFO - [0m13:43:12  [[33mWARNING[0m]: Configuration paths exist in your dbt_project.yml file which do not apply to any resources.
[2023-06-09 13:43:12,129] {subprocess.py:89} INFO - There are 1 unused configuration paths:
[2023-06-09 13:43:12,129] {subprocess.py:89} INFO - - models.part3.example
[2023-06-09 13:43:12,141] {subprocess.py:89} INFO - [0m13:43:12  Found 2 models, 0 tests, 0 snapshots, 0 analyses, 307 macros, 0 operations, 0 seed files, 0 sources, 0 exposures, 0 metrics, 0 groups
[2023-06-09 13:43:12,143] {subprocess.py:89} INFO - [0m13:43:12
[2023-06-09 13:43:32,174] {subprocess.py:89} INFO - [0m13:43:32
[2023-06-09 13:43:32,175] {subprocess.py:89} INFO - [0m13:43:32  Finished running  in 0 hours 0 minutes and 20.03 seconds (20.03s).
[2023-06-09 13:43:32,176] {subprocess.py:89} INFO - [0m13:43:32  Encountered an error:
[2023-06-09 13:43:32,176] {subprocess.py:89} INFO - Database Error
[2023-06-09 13:43:32,176] {subprocess.py:89} INFO -   connection to server at "10.250.12.40", port 5432 failed: timeout expired
[2023-06-09 13:43:32,176] {subprocess.py:89} INFO - 
[2023-06-09 13:43:33,111] {subprocess.py:93} INFO - Command exited with return code 2
[2023-06-09 13:43:33,122] {taskinstance.py:1718} ERROR - Task failed with exception
Traceback (most recent call last):
  File "/home/airflow/.local/lib/python3.7/site-packages/airflow/models/taskinstance.py", line 1334, in _run_raw_task
    self._execute_task_with_callbacks(context)
  File "/home/airflow/.local/lib/python3.7/site-packages/airflow/models/taskinstance.py", line 1460, in _execute_task_with_callbacks
    result = self._execute_task(context, self.task)
  File "/home/airflow/.local/lib/python3.7/site-packages/airflow/models/taskinstance.py", line 1516, in _execute_task
    result = execute_callable(context=context)
  File "/home/airflow/.local/lib/python3.7/site-packages/airflow/operators/bash.py", line 188, in execute
    f'Bash command failed. The command returned a non-zero exit code {result.exit_code}.'
airflow.exceptions.AirflowException: Bash command failed. The command returned a non-zero exit code 2.
[2023-06-09 13:43:33,126] {taskinstance.py:1282} INFO - Marking task as FAILED. dag_id=my_dag, task_id=dbt-1, execution_date=20230609T134308, start_date=20230609T134309, end_date=20230609T134333
[2023-06-09 13:43:33,138] {standard_task_runner.py:92} ERROR - Failed to execute job 30 for task dbt-1
Traceback (most recent call last):
  File "/home/airflow/.local/lib/python3.7/site-packages/airflow/task/task_runner/standard_task_runner.py", line 85, in _start_by_fork
    args.func(args, dag=self.dag)
  File "/home/airflow/.local/lib/python3.7/site-packages/airflow/cli/cli_parser.py", line 48, in command
    return func(*args, **kwargs)
  File "/home/airflow/.local/lib/python3.7/site-packages/airflow/utils/cli.py", line 92, in wrapper
    return f(*args, **kwargs)
  File "/home/airflow/.local/lib/python3.7/site-packages/airflow/cli/commands/task_command.py", line 298, in task_run
    _run_task_by_selected_method(args, dag, ti)
  File "/home/airflow/.local/lib/python3.7/site-packages/airflow/cli/commands/task_command.py", line 107, in _run_task_by_selected_method
    _run_raw_task(args, ti)
  File "/home/airflow/.local/lib/python3.7/site-packages/airflow/cli/commands/task_command.py", line 184, in _run_raw_task
    error_file=args.error_file,
  File "/home/airflow/.local/lib/python3.7/site-packages/airflow/utils/session.py", line 70, in wrapper
    return func(*args, session=session, **kwargs)
  File "/home/airflow/.local/lib/python3.7/site-packages/airflow/models/taskinstance.py", line 1334, in _run_raw_task
    self._execute_task_with_callbacks(context)
  File "/home/airflow/.local/lib/python3.7/site-packages/airflow/models/taskinstance.py", line 1460, in _execute_task_with_callbacks
    result = self._execute_task(context, self.task)
  File "/home/airflow/.local/lib/python3.7/site-packages/airflow/models/taskinstance.py", line 1516, in _execute_task
    result = execute_callable(context=context)
  File "/home/airflow/.local/lib/python3.7/site-packages/airflow/operators/bash.py", line 188, in execute
    f'Bash command failed. The command returned a non-zero exit code {result.exit_code}.'
airflow.exceptions.AirflowException: Bash command failed. The command returned a non-zero exit code 2.
[2023-06-09 13:43:33,164] {local_task_job.py:154} INFO - Task exited with return code 1
[2023-06-09 13:43:33,189] {local_task_job.py:264} INFO - 0 downstream tasks scheduled from follow-on schedule check
